Workbook

Sheet Resumen
A1: Métrica de compatibilidad Word ↔ LibreOffice
A3: Indicadores globales del corpus
A4: Indicador | B4: Valor | F4: Interpretación
A5: Documentos evaluados | B5: =COUNT(Datos!$D$5:$D$22) -> 18 | F5: Total del corpus definitivo congelado.
A6: Índice medio de compatibilidad | B6: =AVERAGE(Datos!$D$5:$D$22) -> 92.111111 | F6: Promedio sobre los 18 documentos.
A7: Índice mediano | B7: =MEDIAN(Datos!$D$5:$D$22) -> 96.3 | F7: Menos sensible al caso extremo que la media.
A8: Índice mínimo (peor caso) | B8: =MIN(Datos!$D$5:$D$22) -> 41.5 | F8: Documento más incompatible del corpus.
A9: Índice máximo (mejor caso) | B9: =MAX(Datos!$D$5:$D$22) -> 99.3 | F9: Documento que mejor se traslada entre suites.
A10: Desviación estándar | B10: =STDEV(Datos!$D$5:$D$22) -> 13.252964 | F10: Dispersión: confirma que la métrica discrimina.
A11: Rango observado | B11: =MAX(Datos!$D$5:$D$22)-MIN(Datos!$D$5:$D$22) -> 57.8 | F11: Amplitud del rango; base para la calibración.
A12: SSIM visual medio | B12: =AVERAGE(Datos!$F$5:$F$22) -> 0.90260556 | F12: Similitud visual media entre ambos motores.
A13: Documentos problemáticos (< umbral) | B13: =COUNTIF(Datos!$D$5:$D$22,"<"&Datos!$D$24) -> 4 | F13: Requieren revisión manual.
A14: % del corpus problemático | B14: =COUNTIF(Datos!$D$5:$D$22,"<"&Datos!$D$24)/COUNT(Datos!$D$5:$D$22) -> 0.22222222 | F14: Proporción de documentos bajo el umbral.
A15: Documentos con paginación rota | B15: =COUNTIF(Datos!$K$5:$K$22,"<>0") -> 2 | F15: Falla dura: cambia lo que se imprime y se firma.
A16: Páginas totales analizadas | B16: =SUM(Datos!$I$5:$I$22) -> 76 | F16: Volumen de evidencia procesada.
A18: Hallazgo principal — el origen del documento predice su compatibilidad
A19: Estrato | B19: n | C19: Índice medio | D19: SSIM medio | E19: Paginación rota | F19: Lectura
A20: A · Nativo Word | B20: =COUNTIF(Datos!$C$5:$C$22,"A · Nativo Word") -> 8 | C20: =AVERAGEIF(Datos!$C$5:$C$22,"A · Nativo Word",Datos!$D$5:$D$22) -> 97.9875 | D20: =AVERAGEIF(Datos!$C$5:$C$22,"A · Nativo Word",Datos!$F$5:$F$22) -> 0.959625 | E20: =COUNTIFS(Datos!$C$5:$C$22,"A · Nativo Word",Datos!$K$5:$K$22,"<>0") -> 0 | F20: Documentos creados originalmente en Word.
A21: B · Convertido a Word | B21: =COUNTIF(Datos!$C$5:$C$22,"B · Convertido a Word") -> 10 | C21: =AVERAGEIF(Datos!$C$5:$C$22,"B · Convertido a Word",Datos!$D$5:$D$22) -> 87.41 | D21: =AVERAGEIF(Datos!$C$5:$C$22,"B · Convertido a Word",Datos!$F$5:$F$22) -> 0.85699 | E21: =COUNTIFS(Datos!$C$5:$C$22,"B · Convertido a Word",Datos!$K$5:$K$22,"<>0") -> 2 | F21: Documentos convertidos a Word desde otro formato.
A22: Diferencia entre estratos (A − B) | C22: =C20-C21 -> 10.5775 | D22: =D20-D21 -> 0.102635 | F22: Brecha sistemática: el estrato B concentra toda la incompatibilidad.

Sheet Datos
A1: DATOS — Corpus definitivo congelado (18 documentos)
A2: Dataset de documentos
A4: # | B4: Documento | C4: Estrato | D4: Índice | E4: Clasificación | F4: SSIM | G4: Fidelidad visual | H4: Conserv. paginación | I4: Págs Word | J4: Págs LibreOffice | K4: Δ Páginas | L4: ¿Paginación rota? | N4: Índice si A | O4: Índice si B
A5: 1 | B5: solicitud_CTI-2026-317.docx | C5: B · Convertido a Word | D5: 41.5 | E5: Critica | F5: 0.831 | G5: 83.1 | H5: 0 | I5: 1 | J5: 2 | K5: =J5-I5 -> 1 | L5: =IF(K5<>0,"SÍ","No") -> SÍ | N5: =IF($C5="A · Nativo Word",$D5,"") | O5: =IF($C5="B · Convertido a Word",$D5,"") -> 41.5
A6: 2 | B6: CÓDIGO DE CONDUCTA 2025_vfinal.docx | C6: B · Convertido a Word | D6: 87.2 | E6: Baja | F6: 0.8352 | G6: 83.5 | H6: 90.9 | I6: 11 | J6: 12 | K6: =J6-I6 -> 1 | L6: =IF(K6<>0,"SÍ","No") -> SÍ | N6: =IF($C6="A · Nativo Word",$D6,"") | O6: =IF($C6="B · Convertido a Word",$D6,"") -> 87.2
A7: 3 | B7: OrdenCompra_IC-ESPOL-047-2026-signed-signed.docx | C7: B · Convertido a Word | D7: 87.3 | E7: Baja | F7: 0.7464 | G7: 74.6 | H7: 100 | I7: 5 | J7: 5 | K7: =J7-I7 -> 0 | L7: =IF(K7<>0,"SÍ","No") -> No | N7: =IF($C7="A · Nativo Word",$D7,"") | O7: =IF($C7="B · Convertido a Word",$D7,"") -> 87.3
A8: 4 | B8: ACTA DE ENTREGA RECEPCIÓN.docx | C8: B · Convertido a Word | D8: 89.2 | E8: Baja | F8: 0.7831 | G8: 78.3 | H8: 100 | I8: 3 | J8: 3 | K8: =J8-I8 -> 0 | L8: =IF(K8<>0,"SÍ","No") -> No | N8: =IF($C8="A · Nativo Word",$D8,"") | O8: =IF($C8="B · Convertido a Word",$D8,"") -> 89.2
A9: 5 | B9: VERIFICACION-PAC-signed.docx | C9: B · Convertido a Word | D9: 92 | E9: Aceptable | F9: 0.8391 | G9: 83.9 | H9: 100 | I9: 2 | J9: 2 | K9: =J9-I9 -> 0 | L9: =IF(K9<>0,"SÍ","No") -> No | N9: =IF($C9="A · Nativo Word",$D9,"") | O9: =IF($C9="B · Convertido a Word",$D9,"") -> 92
A10: 6 | B10: InformeNecesidad_CTIIJN03422026signedsigned_signed.docx | C10: B · Convertido a Word | D10: 92.7 | E10: Aceptable | F10: 0.8534 | G10: 85.3 | H10: 100 | I10: 8 | J10: 8 | K10: =J10-I10 -> 0 | L10: =IF(K10<>0,"SÍ","No") -> No | N10: =IF($C10="A · Nativo Word",$D10,"") | O10: =IF($C10="B · Convertido a Word",$D10,"") -> 92.7
A11: 7 | B11: VERIFICACION-CATE-signed.docx | C11: B · Convertido a Word | D11: 93 | E11: Aceptable | F11: 0.8589 | G11: 85.9 | H11: 100 | I11: 2 | J11: 2 | K11: =J11-I11 -> 0 | L11: =IF(K11<>0,"SÍ","No") -> No | N11: =IF($C11="A · Nativo Word",$D11,"") | O11: =IF($C11="B · Convertido a Word",$D11,"") -> 93
A12: 8 | B12: 07_FormularioESPOLDivulga.docx | C12: A · Nativo Word | D12: 95 | E12: Alta | F12: 0.8996 | G12: 90 | H12: 100 | I12: 2 | J12: 2 | K12: =J12-I12 -> 0 | L12: =IF(K12<>0,"SÍ","No") -> No | N12: =IF($C12="A · Nativo Word",$D12,"") -> 95 | O12: =IF($C12="B · Convertido a Word",$D12,"")
A13: 9 | B13: INFROME DE CONFORMIDAD.docx | C13: B · Convertido a Word | D13: 95.2 | E13: Alta | F13: 0.9028 | G13: 90.3 | H13: 100 | I13: 2 | J13: 2 | K13: =J13-I13 -> 0 | L13: =IF(K13<>0,"SÍ","No") -> No | N13: =IF($C13="A · Nativo Word",$D13,"") | O13: =IF($C13="B · Convertido a Word",$D13,"") -> 95.2
A14: 10 | B14: 08_DelegacionRepresentanteTecnico.docx | C14: A · Nativo Word | D14: 97.4 | E14: Alta | F14: 0.9485 | G14: 94.8 | H14: 100 | I14: 1 | J14: 1 | K14: =J14-I14 -> 0 | L14: =IF(K14<>0,"SÍ","No") -> No | N14: =IF($C14="A · Nativo Word",$D14,"") -> 97.4 | O14: =IF($C14="B · Convertido a Word",$D14,"")
A15: 11 | B15: INEN-DNO-2026-0160-CIR.docx | C15: B · Convertido a Word | D15: 97.8 | E15: Alta | F15: 0.9561 | G15: 95.6 | H15: 100 | I15: 16 | J15: 16 | K15: =J15-I15 -> 0 | L15: =IF(K15<>0,"SÍ","No") -> No | N15: =IF($C15="A · Nativo Word",$D15,"") | O15: =IF($C15="B · Convertido a Word",$D15,"") -> 97.8
A16: 12 | B16: formulario 2026.docx | C16: A · Nativo Word | D16: 98 | E16: Alta | F16: 0.9587 | G16: 95.9 | H16: 100 | I16: 4 | J16: 4 | K16: =J16-I16 -> 0 | L16: =IF(K16<>0,"SÍ","No") -> No | N16: =IF($C16="A · Nativo Word",$D16,"") -> 98 | O16: =IF($C16="B · Convertido a Word",$D16,"")
... A22: 18 | B22: 05_SolicitudCompraSIC.docx | C22: A · Nativo Word | D22: 99.3 | E22: Alta | F22: 0.9863 | G22: 98.6 | H22: 100 | I22: 1 | J22: 1 | K22: =J22-I22 -> 0 | L22: =IF(K22<>0,"SÍ","No") -> No | N22: =IF($C22="A · Nativo Word",$D22,"") -> 99.3 | O22: =IF($C22="B · Convertido a Word",$D22,"")
A24: Umbral de compatibilidad aceptable: | D24: 90
A25: Versión de métricas de esta ejecución: | D25: 1.0-hito1 (2 de 5 metricas)
A26: Ejecución del pipeline cross-engine (Word como referencia vs. LibreOffice) sobre el corpus institucional

Sheet Análisis
A1: ANÁLISIS ESTADÍSTICO — Todos los cálculos por fórmula
A3: A. Estadística descriptiva por estrato
A4: Estadístico | B4: Corpus total | C4: Estrato A (nativo) | D4: Estrato B (convertido) | E4: Diferencia A−B | H4: Comentario
A5: n (documentos) | B5: =COUNT(Datos!$D$5:$D$22) -> 18 | C5: =COUNTIF(Datos!$C$5:$C$22,"A · Nativo Word") -> 8 | D5: =COUNTIF(Datos!$C$5:$C$22,"B · Convertido a Word") -> 10 | E5: =C5-D5 -> -2 | H5: Tamaños de muestra por estrato.
A6: Media del índice | B6: =AVERAGE(Datos!$D$5:$D$22) -> 92.111111 | C6: =AVERAGEIF(Datos!$C$5:$C$22,"A · Nativo Word",Datos!$D$5:$D$22) -> 97.9875 | D6: =AVERAGEIF(Datos!$C$5:$C$22,"B · Convertido a Word",Datos!$D$5:$D$22) -> 87.41 | E6: =C6-D6 -> 10.5775 | H6: Diferencia central entre estratos.
A7: Mediana del índice | B7: =MEDIAN(Datos!$D$5:$D$22) -> 96.3 | C7: =MEDIAN(Datos!$N$5:$N$22) -> 98.5 | D7: =MEDIAN(Datos!$O$5:$O$22) -> 92.35 | E7: =C7-D7 -> 6.15 | H7: Robusta frente al caso extremo (41.5).
A8: Desviación estándar | B8: =STDEV(Datos!$D$5:$D$22) -> 13.252964 | C8: =STDEV(Datos!$N$5:$N$22) -> 1.3249663 | D8: =STDEV(Datos!$O$5:$O$22) -> 16.587643 | E8: =C8-D8 -> -15.262676 | H8: El estrato B es mucho más disperso.
A9: Mínimo | B9: =MIN(Datos!$D$5:$D$22) -> 41.5 | C9: =MIN(Datos!$N$5:$N$22) -> 95 | D9: =MIN(Datos!$O$5:$O$22) -> 41.5 | E9: =C9-D9 -> 53.5 | H9: El peor caso pertenece al estrato B.
A10: Máximo | B10: =MAX(Datos!$D$5:$D$22) -> 99.3 | C10: =MAX(Datos!$N$5:$N$22) -> 99.3 | D10: =MAX(Datos!$O$5:$O$22) -> 98.2 | E10: =C10-D10 -> 1.1 | H10: Ambos estratos alcanzan valores altos.
A11: SSIM medio | B11: =AVERAGE(Datos!$F$5:$F$22) -> 0.90260556 | C11: =AVERAGEIF(Datos!$C$5:$C$22,"A · Nativo Word",Datos!$F$5:$F$22) -> 0.959625 | D11: =AVERAGEIF(Datos!$C$5:$C$22,"B · Convertido a Word",Datos!$F$5:$F$22) -> 0.85699 | E11: =C11-D11 -> 0.102635 | H11: Divergencia visual media.
A12: Documentos bajo umbral | B12: =COUNTIF(Datos!$D$5:$D$22,"<"&Datos!$D$24) -> 4 | C12: =COUNTIFS(Datos!$C$5:$C$22,"A · Nativo Word",Datos!$D$5:$D$22,"<"&Datos!$D$24) -> 0 | D12: =COUNTIFS(Datos!$C$5:$C$22,"B · Convertido a Word",Datos!$D$5:$D$22,"<"&Datos!$D$24) -> 4 | E12: =C12-D12 -> -4 | H12: Todos los problemáticos son del estrato B.
A13: Paginación rota | B13: =COUNTIF(Datos!$K$5:$K$22,"<>0") -> 2 | C13: =COUNTIFS(Datos!$C$5:$C$22,"A · Nativo Word",Datos!$K$5:$K$22,"<>0") -> 0 | D13: =COUNTIFS(Datos!$C$5:$C$22,"B · Convertido a Word",Datos!$K$5:$K$22,"<>0") -> 2 | E13: =C13-D13 -> -2 | H13: Falla dura, exclusiva del estrato B.
A15: Nota: los estadísticos por estrato se calculan sobre las columnas auxiliares N y O de la hoja Datos, que segmentan el índice por estrato. No se usan fórmulas matriciales.
A17: B. Distribución por clasificación de compatibilidad
A18: Clasificación | B18: Criterio | C18: N.º documentos | D18: % del corpus | H18: Acción recomendada
A19: Alta | B19: Índice ≥ 95 | C19: =COUNTIF(Datos!$E$5:$E$22,"Alta") -> 11 | D19: =COUNTIF(Datos!$E$5:$E$22,"Alta")/COUNT(Datos!$D$5:$D$22) -> 0.61111111 | H19: Trasladable sin intervención.
A20: Aceptable | B20: 90 ≤ Índice < 95 | C20: =COUNTIF(Datos!$E$5:$E$22,"Aceptable") -> 3 | D20: =COUNTIF(Datos!$E$5:$E$22,"Aceptable")/COUNT(Datos!$D$5:$D$22) -> 0.16666667 | H20: Revisión ligera antes de publicar.
A21: Baja | B21: 70 ≤ Índice < 90 | C21: =COUNTIF(Datos!$E$5:$E$22,"Baja") -> 3 | D21: =COUNTIF(Datos!$E$5:$E$22,"Baja")/COUNT(Datos!$D$5:$D$22) -> 0.16666667 | H21: Requiere corrección manual.
A22: Crítica | B22: Índice < 70 | C22: =COUNTIF(Datos!$E$5:$E$22,"Critica") -> 1 | D22: =COUNTIF(Datos!$E$5:$E$22,"Critica")/COUNT(Datos!$D$5:$D$22) -> 0.055555556 | H22: No trasladable: rehacer o fijar formato.
A23: TOTAL | C23: =SUM(C19:C22) -> 18 | D23: =SUM(D19:D22) -> 1
A25: C. Valor añadido del índice compuesto frente al SSIM aislado
A26: Documento | B26: SSIM | C26: Ranking por SSIM | D26: Índice compuesto | E26: Ranking por índice | F26: Salto de posición | G26: |Salto| | H26: Lectura
A27: solicitud_CTI-2026-317.docx | B27: =Datos!F5 -> 0.831 | C27: =RANK(B27,$B$27:$B$44,1) -> 3 | D27: =Datos!D5 -> 41.5 | E27: =RANK(D27,$D$27:$D$44,1) -> 1 | F27: =C27-E27 -> 2 | G27: =ABS(F27) -> 2 | H27: =IF(ABS(F27)>=3,"Reordenamiento relevante","")
A28: CÓDIGO DE CONDUCTA 2025_vfinal.docx | B28: =Datos!F6 -> 0.8352 | C28: =RANK(B28,$B$27:$B$44,1) -> 4 | D28: =Datos!D6 -> 87.2 | E28: =RANK(D28,$D$27:$D$44,1) -> 2 | F28: =C28-E28 -> 2 | G28: =ABS(F28) -> 2 | H28: =IF(ABS(F28)>=3,"Reordenamiento relevante","")
A29: OrdenCompra_IC-ESPOL-047-2026-signed-signed. | B29: =Datos!F7 -> 0.7464 | C29: =RANK(B29,$B$27:$B$44,1) -> 1 | D29: =Datos!D7 -> 87.3 | E29: =RANK(D29,$D$27:$D$44,1) -> 3 | F29: =C29-E29 -> -2 | G29: =ABS(F29) -> 2 | H29: =IF(ABS(F29)>=3,"Reordenamiento relevante","")
A30: ACTA DE ENTREGA RECEPCIÓN.docx | B30: =Datos!F8 -> 0.7831 | C30: =RANK(B30,$B$27:$B$44,1) -> 2 | D30: =Datos!D8 -> 89.2 | E30: =RANK(D30,$D$27:$D$44,1) -> 4 | F30: =C30-E30 -> -2 | G30: =ABS(F30) -> 2 | H30: =IF(ABS(F30)>=3,"Reordenamiento relevante","")
A31: VERIFICACION-PAC-signed.docx | B31: =Datos!F9 -> 0.8391 | C31: =RANK(B31,$B$27:$B$44,1) -> 5 | D31: =Datos!D9 -> 92 | E31: =RANK(D31,$D$27:$D$44,1) -> 5 | F31: =C31-E31 -> 0 | G31: =ABS(F31) -> 0 | H31: =IF(ABS(F31)>=3,"Reordenamiento relevante","")
A32: InformeNecesidad_CTIIJN03422026signedsigned_ | B32: =Datos!F10 -> 0.8534 | C32: =RANK(B32,$B$27:$B$44,1) -> 6 | D32: =Datos!D10 -> 92.7 | E32: =RANK(D32,$D$27:$D$44,1) -> 6 | F32: =C32-E32 -> 0 | G32: =ABS(F32) -> 0 | H32: =IF(ABS(F32)>=3,"Reordenamiento relevante","")
A33: VERIFICACION-CATE-signed.docx | B33: =Datos!F11 -> 0.8589 | C33: =RANK(B33,$B$27:$B$44,1) -> 7 | D33: =Datos!D11 -> 93 | E33: =RANK(D33,$D$27:$D$44,1) -> 7 | F33: =C33-E33 -> 0 | G33: =ABS(F33) -> 0 | H33: =IF(ABS(F33)>=3,"Reordenamiento relevante","")
A34: 07_FormularioESPOLDivulga.docx | B34: =Datos!F12 -> 0.8996 | C34: =RANK(B34,$B$27:$B$44,1) -> 8 | D34: =Datos!D12 -> 95 | E34: =RANK(D34,$D$27:$D$44,1) -> 8 | F34: =C34-E34 -> 0 | G34: =ABS(F34) -> 0 | H34: =IF(ABS(F34)>=3,"Reordenamiento relevante","")
A35: INFROME DE CONFORMIDAD.docx | B35: =Datos!F13 -> 0.9028 | C35: =RANK(B35,$B$27:$B$44,1) -> 9 | D35: =Datos!D13 -> 95.2 | E35: =RANK(D35,$D$27:$D$44,1) -> 9 | F35: =C35-E35 -> 0 | G35: =ABS(F35) -> 0 | H35: =IF(ABS(F35)>=3,"Reordenamiento relevante","")
A36: 08_DelegacionRepresentanteTecnico.docx | B36: =Datos!F14 -> 0.9485 | C36: =RANK(B36,$B$27:$B$44,1) -> 10 | D36: =Datos!D14 -> 97.4 | E36: =RANK(D36,$D$27:$D$44,1) -> 10 | F36: =C36-E36 -> 0 | G36: =ABS(F36) -> 0 | H36: =IF(ABS(F36)>=3,"Reordenamiento relevante","")
A37: INEN-DNO-2026-0160-CIR.docx | B37: =Datos!F15 -> 0.9561 | C37: =RANK(B37,$B$27:$B$44,1) -> 11 | D37: =Datos!D15 -> 97.8 | E37: =RANK(D37,$D$27:$D$44,1) -> 11 | F37: =C37-E37 -> 0 | G37: =ABS(F37) -> 0 | H37: =IF(ABS(F37)>=3,"Reordenamiento relevante","")
A38: formulario 2026.docx | B38: =Datos!F16 -> 0.9587 | C38: =RANK(B38,$B$27:$B$44,1) -> 12 | D38: =Datos!D16 -> 98 | E38: =RANK(D38,$D$27:$D$44,1) -> 12 | F38: =C38-E38 -> 0 | G38: =ABS(F38) -> 0 | H38: =IF(ABS(F38)>=3,"Reordenamiento relevante","")
... A44: 05_SolicitudCompraSIC.docx | B44: =Datos!F22 -> 0.9863 | C44: =RANK(B44,$B$27:$B$44,1) -> 18 | D44: =Datos!D22 -> 99.3 | E44: =RANK(D44,$D$27:$D$44,1) -> 18 | F44: =C44-E44 -> 0 | G44: =ABS(F44) -> 0 | H44: =IF(ABS(F44)>=3,"Reordenamiento relevante","")
A45: Documento con mayor discrepancia de ranking: | D45: =INDEX(A27:A44,MATCH(MAX(G27:G44),G27:G44,0)) -> solicitud_CTI-2026-317.docx
A46: Un salto grande significa que el índice compuesto lo evalúa de forma muy distinta a la similitud visual.
A48: D. Prueba decisiva — ¿qué dimensión aísla realmente el peor caso?
A49: Criterio de ordenamiento | B49: Peor documento | D49: Valor del peor | E49: Valor del 2.º peor | F49: Brecha | G49: Brecha relativa | H49: Lectura
A50: Por SSIM (visual aislado) | B50: =INDEX($A$27:$A$44,MATCH(MIN($B$27:$B$44),$B$27:$B$44,0)) -> OrdenCompra_IC-ESPOL-047-2026-signed-signed. | D50: =MIN($B$27:$B$44) -> 0.7464 | E50: =SMALL($B$27:$B$44,2) -> 0.7831 | F50: =E50-D50 -> 0.0367 | G50: =F50/(MAX($B$27:$B$44)-MIN($B$27:$B$44)) -> 0.15298041 | H50: El peor documento visual apenas se separa del siguiente: quedan agrupados.
...

Sheet Problemáticos y muestra
A1: ARCHIVOS PROBLEMÁTICOS Y SELECCIÓN PARA VALIDACIÓN
A3: A. Archivos problemáticos identificados (índice < umbral o falla dura)
A4: Documento | B4: Estrato | C4: Índice | D4: Clasificación | E4: Δ Páginas | F4: Tipo de falla | G4: Motivo
A5: solicitud_CTI-2026-317.docx | B5: B · Convertido a Word | C5: =Datos!D5 -> 41.5 | D5: =Datos!E5 -> Critica | E5: =Datos!K5 -> 1 | F5: Falla dura | G5: Cambio de paginación (1→2); Divergencia visual alta (SSIM 0.831)
A6: CÓDIGO DE CONDUCTA 2025_vfinal.docx | B6: B · Convertido a Word | C6: =Datos!D6 -> 87.2 | D6: =Datos!E6 -> Baja | E6: =Datos!K6 -> 1 | F6: Falla dura | G6: Cambio de paginación (11→12); Divergencia visual alta (SSIM 0.835)
A7: OrdenCompra_IC-ESPOL-047-2026-signed-signed.docx | B7: B · Convertido a Word | C7: =Datos!D7 -> 87.3 | D7: =Datos!E7 -> Baja | E7: =Datos!K7 -> 0 | F7: Degradación visual | G7: Divergencia visual alta (SSIM 0.746)
A8: ACTA DE ENTREGA RECEPCIÓN.docx | B8: B · Convertido a Word | C8: =Datos!D8 -> 89.2 | D8: =Datos!E8 -> Baja | E8: =Datos!K8 -> 0 | F8: Degradación visual | G8: Divergencia visual alta (SSIM 0.783)
A10: Total problemáticos: | C10: =COUNT(C5:C8) -> 4
A12: B. Selección para validación humana (criterio determinista y auditable)
A13: Documento | B13: Estrato | C13: Índice | D13: Clasificación | E13: Págs | F13: Criterio | G13: Justificación
A14: solicitud_CTI-2026-317.docx | B14: B · Convertido a Word | C14: =Datos!D5 -> 41.5 | D14: =Datos!E5 -> Critica | E14: =Datos!I5 -> 1 | F14: falla dura: cambio de paginación | G14: Entra obligatoriamente: mayor esfuerzo de corrección esperado.
A15: CÓDIGO DE CONDUCTA 2025_vfinal.docx | B15: B · Convertido a Word | C15: =Datos!D6 -> 87.2 | D15: =Datos!E6 -> Baja | E15: =Datos!I6 -> 11 | F15: falla dura: cambio de paginación | G15: Entra obligatoriamente: mayor esfuerzo de corrección esperado.
A16: VERIFICACION-PAC-signed.docx | B16: B · Convertido a Word | C16: =Datos!D9 -> 92 | D16: =Datos!E9 -> Aceptable | E16: =Datos!I9 -> 2 | F16: cobertura del rango (cuartil bajo) | G16: Cubre la zona baja del rango para dar variabilidad a la calibración.
A17: INFROME DE CONFORMIDAD.docx | B17: B · Convertido a Word | C17: =Datos!D13 -> 95.2 | D17: =Datos!E13 -> Alta | E17: =Datos!I13 -> 2 | F17: cobertura del rango (mediana) | G17: Representa el comportamiento típico del corpus.
A18: NTE INEN-ISO 2859-1_EXTRACTO.docx | B18: B · Convertido a Word | C18: =Datos!D17 -> 98.2 | D18: =Datos!E17 -> Alta | E18: =Datos!I17 -> 12 | F18: cobertura del rango (cuartil alto) | G18: Cubre la zona alta del rango.
A19: 04_InformeNecesidad.docx | B19: A · Nativo Word | C19: =Datos!D21 -> 98.7 | D19: =Datos!E21 -> Alta | E19: =Datos!I21 -> 3 | F19: cobertura del rango (mejor caso) | G19: Control: debería requerir esfuerzo casi nulo.
A20: Rango de índices cubierto por la muestra: | C20: =MIN(C14:C19) -> 41.5 | D20: ="a "&TEXT(MAX(C14:C19),"0.0") -> a 99
A21: La muestra cubre prácticamente todo el rango observado del corpus. Sin esa variabilidad no habría contra qué correlacionar el tiempo de edición humano en la fase de calibración.

Sheet Metodología
A1: METODOLOGÍA — Métricas congeladas, pesos y reglas
A3: A. Las cinco métricas prioritarias (conjunto congelado v2.0)
A4: Métrica | B4: Qué mide | C4: Peso | D4: Cómo se obtiene | E4: Justificación del peso
A5: 1. Fidelidad visual | B5: Divergencia visual de la maquetación | C5: 0.3 | D5: SSIM sobre páginas representativas | E5: Es lo que el usuario percibe primero.
A6: 2. Conservación de paginación | B6: Que el documento ocupe las mismas páginas | C6: 0.25 | D6: Conteo de páginas de ambos renders | E6: Falla dura: altera impresión, referencias y firma.
A7: 3. Conservación de fuentes | B7: Sustitución tipográfica entre motores | C7: 0.2 | D7: pdffonts sobre ambos PDF | E7: Causa directa del reflujo; se pondera por debajo del efecto.
A8: 4. Estabilidad del flujo | B8: Dónde cae cada salto de línea (reflujo) | C8: 0.15 | D8: pdftotext + comparación de secuencias | E8: Mecanismo causal, ya reflejado en la divergencia visual.
A9: 5. Integridad de objetos | B9: Que imágenes y objetos se rendericen | C9: 0.1 | D9: pdfimages sobre ambos PDF | E9: Poco frecuente en este corpus, pero grave cuando ocurre.
A10: Suma de pesos (control) | C10: =SUM(C5:C9) -> 1 | D10: =IF(ABS(C10-1)<0.0001,"✓ Correcto: los pesos suman 100%","✗ ERROR: los pesos no suman 100%") -> ✓ Correcto: los pesos suman 100%
A13: B. Diseño de la medición y alcance
A14: Comparación cross-engine | B14: La referencia es el PDF exportado desde Microsoft Word; el objetivo es el render de LibreOffice del mismo documento. Ambos se rasterizan al mismo DPI antes de comparar.
A15: Insumo manual | B15: Se requiere un PDF exportado desde Word por documento, porque Word no ejecuta en Linux. Es una restricción del entorno, no del método.
A16: Versión de métricas de estos datos | B16: Los 18 resultados provienen del pipeline con 2 de las 5 métricas. Las otras tres están implementadas y probadas, pero requieren los PDF de Word y los archivos fuente. Al re-ejecutar, los índices CAMBIARÁN de valor; se espera que el orden relativo se mantenga, pero debe verificarse, no asumirse.
A17: Pesos provisionales | B17: Están justificados conceptualmente, no empíricamente. Calibrarlos contra el tiempo de edición humano es el objetivo de la fase siguiente.
A18: Tamaño del corpus | B18: 18 documentos alcanzan para detectar una diferencia sistemática entre estratos y para seleccionar casos de validación; no para afirmaciones estadísticas fuertes.

Sheet Gráficas
A1: GRÁFICAS — Generadas a partir de la hoja Datos
A3: Tabla auxiliar 1 — Índice por documento (ordenado)
A4: Documento | B4: Índice | C4: Umbral
A5: =Datos!B5 -> solicitud_CTI-2026-317.docx | B5: =Datos!D5 -> 41.5 | C5: =Datos!$D$24 -> 90
A6: =Datos!B6 -> CÓDIGO DE CONDUCTA 2025_vfinal.docx | B6: =Datos!D6 -> 87.2 | C6: =Datos!$D$24 -> 90
A7: =Datos!B7 -> OrdenCompra_IC-ESPOL-047-2026-signed-signed.docx | B7: =Datos!D7 -> 87.3 | C7: =Datos!$D$24 -> 90
A8: =Datos!B8 -> ACTA DE ENTREGA RECEPCIÓN.docx | B8: =Datos!D8 -> 89.2 | C8: =Datos!$D$24 -> 90
A9: =Datos!B9 -> VERIFICACION-PAC-signed.docx | B9: =Datos!D9 -> 92 | C9: =Datos!$D$24 -> 90
A10: =Datos!B10 -> InformeNecesidad_CTIIJN03422026signedsigned_signed.docx | B10: =Datos!D10 -> 92.7 | C10: =Datos!$D$24 -> 90
A11: =Datos!B11 -> VERIFICACION-CATE-signed.docx | B11: =Datos!D11 -> 93 | C11: =Datos!$D$24 -> 90
A12: =Datos!B12 -> 07_FormularioESPOLDivulga.docx | B12: =Datos!D12 -> 95 | C12: =Datos!$D$24 -> 90
A13: =Datos!B13 -> INFROME DE CONFORMIDAD.docx | B13: =Datos!D13 -> 95.2 | C13: =Datos!$D$24 -> 90
A14: =Datos!B14 -> 08_DelegacionRepresentanteTecnico.docx | B14: =Datos!D14 -> 97.4 | C14: =Datos!$D$24 -> 90
A15: =Datos!B15 -> INEN-DNO-2026-0160-CIR.docx | B15: =Datos!D15 -> 97.8 | C15: =Datos!$D$24 -> 90
A16: =Datos!B16 -> formulario 2026.docx | B16: =Datos!D16 -> 98 | C16: =Datos!$D$24 -> 90
... A22: =Datos!B22 -> 05_SolicitudCompraSIC.docx | B22: =Datos!D22 -> 99.3 | C22: =Datos!$D$24 -> 90
A25: Tabla auxiliar 2 — Comparación de estratos
A26: Estrato | B26: Índice medio | C26: SSIM medio ×100 | D26: Paginación rota
A27: A · Nativo Word | B27: =AVERAGEIF(Datos!$C$5:$C$22,"A · Nativo Word",Datos!$D$5:$D$22) -> 97.9875 | C27: =AVERAGEIF(Datos!$C$5:$C$22,"A · Nativo Word",Datos!$F$5:$F$22)*100 -> 95.9625 | D27: =COUNTIFS(Datos!$C$5:$C$22,"A · Nativo Word",Datos!$K$5:$K$22,"<>0") -> 0
A28: B · Convertido a Word | B28: =AVERAGEIF(Datos!$C$5:$C$22,"B · Convertido a Word",Datos!$D$5:$D$22) -> 87.41 | C28: =AVERAGEIF(Datos!$C$5:$C$22,"B · Convertido a Word",Datos!$F$5:$F$22)*100 -> 85.699 | D28: =COUNTIFS(Datos!$C$5:$C$22,"B · Convertido a Word",Datos!$K$5:$K$22,"<>0") -> 2
A31: Tabla auxiliar 3 — SSIM frente a índice compuesto
A32: Documento | B32: SSIM | C32: Índice compuesto
A33: =Datos!B5 -> solicitud_CTI-2026-317.docx | B33: =Datos!F5 -> 0.831 | C33: =Datos!D5 -> 41.5
A34: =Datos!B6 -> CÓDIGO DE CONDUCTA 2025_vfinal.docx | B34: =Datos!F6 -> 0.8352 | C34: =Datos!D6 -> 87.2
A35: =Datos!B7 -> OrdenCompra_IC-ESPOL-047-2026-signed-signed.docx | B35: =Datos!F7 -> 0.7464 | C35: =Datos!D7 -> 87.3
A36: =Datos!B8 -> ACTA DE ENTREGA RECEPCIÓN.docx | B36: =Datos!F8 -> 0.7831 | C36: =Datos!D8 -> 89.2
A37: =Datos!B9 -> VERIFICACION-PAC-signed.docx | B37: =Datos!F9 -> 0.8391 | C37: =Datos!D9 -> 92
A38: =Datos!B10 -> InformeNecesidad_CTIIJN03422026signedsigned_signed.docx | B38: =Datos!F10 -> 0.8534 | C38: =Datos!D10 -> 92.7
A39: =Datos!B11 -> VERIFICACION-CATE-signed.docx | B39: =Datos!F11 -> 0.8589 | C39: =Datos!D11 -> 93
A40: =Datos!B12 -> 07_FormularioESPOLDivulga.docx | B40: =Datos!F12 -> 0.8996 | C40: =Datos!D12 -> 95
A41: =Datos!B13 -> INFROME DE CONFORMIDAD.docx | B41: =Datos!F13 -> 0.9028 | C41: =Datos!D13 -> 95.2
A42: =Datos!B14 -> 08_DelegacionRepresentanteTecnico.docx | B42: =Datos!F14 -> 0.9485 | C42: =Datos!D14 -> 97.4
A43: =Datos!B15 -> INEN-DNO-2026-0160-CIR.docx | B43: =Datos!F15 -> 0.9561 | C43: =Datos!D15 -> 97.8
A44: =Datos!B16 -> formulario 2026.docx | B44: =Datos!F16 -> 0.9587 | C44: =Datos!D16 -> 98
... A50: =Datos!B22 -> 05_SolicitudCompraSIC.docx | B50: =Datos!F22 -> 0.9863 | C50: =Datos!D22 -> 99.3
A52: En la dispersión, el punto inferior aislado corresponde al documento cuya paginación se rompe: su SSIM es intermedio, pero el índice compuesto lo sitúa muy por debajo del resto.
